Workbook

Sheet README
A1: OI critical review: paper selection and scoring workbook
A3: Purpose | B3: Select papers by a written protocol, score each on a rigor rubric (two raters), log every claim, and analyze the results without rebuilding anything.
A4: Workflow | B4: 1) Check Protocol and Screening_Log. 2) Full-text check the Include and Maybe records; add new records to the log. 3) Rater 1 and Rater 2 score on Scoring without seeing each other's columns. 4) Discuss every DISCUSS cell and overwrite it with the agreed value. 5) Log claims on Claims while reading. 6) Read the tiers on Tiers (set cut-offs first), compare papers within each tier, write the findings per tier, then check the candidate determining factor. 7) Read Analysis.
A5: Sheets | B5: Protocol: criteria and search record. Screening_Log: every record with decision and reason. Flow: PRISMA-style counts. Scoring: one row per empirical paper (9 items, including Replication), with an automatic tier. Scoring_Reviews: reviews, roadmaps and company pages on a 4-item review rubric. Tiers: cut-offs, tier comparison, findings per tier, determining factor. Claims: claims audit. Rubric_Anchors: what 0, 1, 2 mean (empirical and review rubrics). Analysis: item means, Cohen's kappa, COI and peer-review comparisons, claim tags. Codes and Lists: reference values for dropdowns.
A6: Color key | B6: Blue text on yellow fill = team input (edit these). Black text = formula or fixed content (do not overwrite, except DISCUSS cells in the Final block, which you replace with the agreed score).
A7: Pre-filled vs checked | B7: Pre-filled and unverified: screening decisions (abstracts only), claim categories, peer-review status. Taken from the team's OI Notes and not re-checked against PDFs: COI for the five seed papers and claims C01-C11.
A8: Capacity | B8: Scoring holds up to 100 empirical papers (rows 6-105), Scoring_Reviews up to 50, Claims up to 200 rows, Screening_Log up to 400 records. Extend the formula ranges if you go past that.
A9: Stats step | B9: Kappa and group comparisons are computed as soon as Rater 2 scores exist. Weighted kappa and exact tests (Mann-Whitney) need to be run outside the sheet.
A10: What this workbook does not do | B10: It does not score papers. Scores need a person reading the full text; an AI second pass can help flag misreads but should never replace a human rater.
A12: Example row (fictional, for format only; not in any formula range)
A13: Field | B13: Example value
A14: Paper ID / title | B14: example:Doe-2024 / Doe et al. 2024 (EXAMPLE ONLY, not a real paper)
A15: R1 scores SM, UA, CT, CF, EA, RB, TR, CC, RP | B15: 2, 1, 2, 0, NA, 1, 2, 1, 0
A16: R2 scores | B16: 2, 1, 1, 0, NA, 1, 2, 2, 0 (Final block would show DISCUSS for CT and CC)
A17: COI / affiliation | B17: Academic, none declared
A18: Claim row | B18: Learning/adaptation | 'Cultures improve over 5 days' | Demonstrated under constraints | Measured | Comparator: none | n = 8 cultures

Sheet Protocol
A1: Search and selection protocol (v1, written before the searches were run)
A3: Review question | B3: How well supported are published computational, learning, and efficiency claims about brain organoids and neural cultures used as biological computing substrates (organoid intelligence, biocomputing, wetware)?
A4: Why include weak papers | B4: Selection is by 'makes a claim in scope', not by quality. Quality is scored afterwards, so low-rigor and hyped papers stay in the corpus. Screening only for rigor would hide the thing being studied.
A5: Inclusion (all required) | B5: I1: living neural tissue (organoid, 2D culture, assembloid) on an electrode or similar interface used as a computational or learning substrate, OR a review/roadmap/grey source making explicit claims about such systems. I2: at least one explicit claim about (a) computational performance, (b) learning or adaptation, or (c) efficiency (energy, sample, or cost) relative to AI/silicon. I3: enough text accessible to code the rubric items. I4: English; published or posted 2020 onward.
A6: Exclusion codes | B6: See the Codes sheet (E1-E8). Duplicates and preprints of an included paper are logged as E3 and the version of record is kept.
A7: Context sources (not scored) | B7: Codes C1-C4: critiques and skeptical sources, commentary and press (for tracing how claims propagate), OI-specific ethics papers (ethics arm), and comparator literature on AI/neuromorphic energy and sample efficiency.
A8: Paper-index searches (from 2020-01-01 unless noted) | B8: Q1 organoid intelligence biocomputing brain organoids as computational substrate (top 40) Q2 brain organoid reservoir computing learning on multielectrode array (top 40) Q3 in vitro neuronal cultures closed-loop learning game-playing Pong sample efficiency versus reinforcement learning (top 40) Q4 energy efficiency biological neural networks versus silicon computing organoid (top 30) Q5 ethics of organoid intelligence sentience consciousness brain organoid computing (top 30) Q6 FinalSpark Neuroplatform electrophysiological remote access human brain organoids (from 2022, top 15) Q7 Smirnova Hartung organoid intelligence OI roadmap biocomputing (from 2022, top 15) Q8 critique skeptical hype claims synthetic biological intelligence organoid intelligence limitations (from 2022, top 25)
A9: Web search (grey literature) | B9: W1 Cortical Labs CL1 biological computer FinalSpark Unconventional AI whitepaper energy claims (top 10). Company pages and the InsightAce market report are included as grey literature and scored mainly on EA, CC and TR.
A10: Index coverage | B10: The paper index covers PubMed, bioRxiv, medRxiv, arXiv and other scientific sources. Google Scholar, Web of Science and Scopus were not searched; adding at least one of them is the main way to reduce coverage bias.
A11: Citation chaining (not completed) | B11: Attempted citers of Kagan 2022 and Cai 2023 through the index's citation graph; the seed IDs did not resolve and no results came back. Do this by hand with 'Cited by' in Google Scholar or Scopus, then add new records to Screening_Log.
A12: Known gaps | B12: 1) Unconventional AI materials were not found by the search; look at their site and any preprints by hand. 2) The Smirnova 2023 seed was not returned by the index and was added manually. 3) Screening used titles and abstracts only, by one screener, so every Include/Maybe needs a full-text check and a second screener on a ~20% random sample (Screening_Log columns K-L). 4) The search is not exhaustive, so describe the corpus as a systematic-style sample, not a complete census of the field.
A13: Rubric changes | B13: Do not change the rubric midstream without noting the version and date here. Re-score earlier papers if an anchor changes.

Sheet Screening_Log
A1: Screening log (every record, with decision and reason)
A2: Screened on title/abstract only, by a single screener (Claude). Blue-on-yellow cells are for the team: second-screener decision on a random ~20% sample, and any overrides. Counts on the Flow sheet update automatically.
A3: Years left blank where the identifier does not show one; fill in when you open the record.
A5: # | B5: Record ID | C5: Title | D5: Year | E5: Record type | F5: Found via | G5: Decision | H5: Code | I5: Reason (auto from Codes) | J5: Notes | K5: 2nd screener decision | L5: Agree?
A6: 1 | B6: doi:10.1016/j.neuron.2022.09.001 | C6: Kagan et al. In vitro neurons learn and exhibit sentience when embodied in a simulated game-world (DishBrain), Neuron | D6: 2022 | E6: Empirical | F6: Seed; Q3 | G6: Include | H6: I | I6: =IF(H6="","",IFERROR(INDEX(Codes!$B$2:$B$30,MATCH(H6,Codes!$A$2:$A$30,0)),"")) -> Include: empirical paper with a computational, learning, or efficiency claim about living neural tissue as a substrate | J6: Team seed. Index ID pmcid:PMC9747182 | L6: =IF(K6="","",IF(K6=G6,"Y","N"))
A7: 2 | B7: doi:10.1038/s41928-023-01069-w | C7: Cai et al. Brain organoid reservoir computing for artificial intelligence (Brainoware), Nat Electron | D7: 2023 | E7: Empirical | F7: Seed; Q1 | G7: Include | H7: I | I7: =IF(H7="","",IFERROR(INDEX(Codes!$B$2:$B$30,MATCH(H7,Codes!$A$2:$A$30,0)),"")) -> Include: empirical paper with a computational, learning, or efficiency claim about living neural tissue as a substrate | J7: Team seed. Preprint version logged separately as duplicate | L7: =IF(K7="","",IF(K7=G7,"Y","N"))
A8: 3 | B8: doi:10.34133/cbsystems.0336 | C8: Khajehnejad et al. Dynamic network plasticity and sample efficiency in biological neural cultures: comparison with deep RL, Cyborg Bionic Syst | D8: 2025 | E8: Empirical | F8: Seed; Q3 | G8: Include | H8: I | I8: =IF(H8="","",IFERROR(INDEX(Codes!$B$2:$B$30,MATCH(H8,Codes!$A$2:$A$30,0)),"")) -> Include: empirical paper with a computational, learning, or efficiency claim about living neural tissue as a substrate | J8: Team seed; cite 2025 published version. Index ID pmcid:PMC12320521 | L8: =IF(K8="","",IF(K8=G8,"Y","N"))
A9: 4 | B9: doi:10.3389/frai.2024.1376042 | C9: Jordan et al. Open and remotely accessible Neuroplatform for research in wetware computing (FinalSpark), Front AI | D9: 2024 | E9: Empirical | F9: Seed; Q6 | G9: Include | H9: I | I9: =IF(H9="","",IFERROR(INDEX(Codes!$B$2:$B$30,MATCH(H9,Codes!$A$2:$A$30,0)),"")) -> Include: empirical paper with a computational, learning, or efficiency claim about living neural tissue as a substrate | J9: Team seed. Index ID pmcid:PMC11097343 | L9: =IF(K9="","",IF(K9=G9,"Y","N"))
A10: 5 | B10: doi:10.3389/fsci.2023.1017235 | C10: Smirnova et al. Organoid intelligence (OI): the new frontier in biocomputing and intelligence-in-a-dish, Front Sci | D10: 2023 | E10: Review/roadmap | F10: Seed (manual add) | G10: Include | H10: R | I10: =IF(H10="","",IFERROR(INDEX(Codes!$B$2:$B$30,MATCH(H10,Codes!$A$2:$A$30,0)),"")) -> Include: review or roadmap that makes explicit claims about such systems | J10: Team seed. Not returned by index search; added from team notes | L10: =IF(K10="","",IF(K10=G10,"Y","N"))
A11: 6 | B11: pmid:42399712 | C11: Computing inspired by the brain: a journey from algorithms to organoids (Nat Comput Sci) | D11: 2026 | E11: Review/roadmap | F11: Q1 | G11: Include | H11: R | I11: =IF(H11="","",IFERROR(INDEX(Codes!$B$2:$B$30,MATCH(H11,Codes!$A$2:$A$30,0)),"")) -> Include: review or roadmap that makes explicit claims about such systems | L11: =IF(K11="","",IF(K11=G11,"Y","N"))
A12: 7 | B12: arxiv:2503.19770 | C12: Brain Organoid Computing: an Overview | D12: 2025 | E12: Review/roadmap | F12: Q1 | G12: Include | H12: R | I12: =IF(H12="","",IFERROR(INDEX(Codes!$B$2:$B$30,MATCH(H12,Codes!$A$2:$A$30,0)),"")) -> Include: review or roadmap that makes explicit claims about such systems | L12: =IF(K12="","",IF(K12=G12,"Y","N"))
A13: 8 | B13: pmcid:PMC10013972 | C13: First Organoid Intelligence (OI) workshop to form an OI community | D13: 2023 | E13: Review/roadmap | F13: Q1 | G13: Include | H13: R | I13: =IF(H13="","",IFERROR(INDEX(Codes!$B$2:$B$30,MATCH(H13,Codes!$A$2:$A$30,0)),"")) -> Include: review or roadmap that makes explicit claims about such systems | L13: =IF(K13="","",IF(K13=G13,"Y","N"))
A14: 9 | B14: pmcid:PMC10002682 | C14: Brain Organoid Computing for Artificial Intelligence (bioRxiv preprint of Brainoware) | D14: 2023 | E14: Empirical | F14: Q1; Q2 | G14: Exclude | H14: E3 | I14: =IF(H14="","",IFERROR(INDEX(Codes!$B$2:$B$30,MATCH(H14,Codes!$A$2:$A$30,0)),"")) -> Exclude: duplicate or earlier version of an included record (version of record kept) | J14: Preprint of Cai 2023; version of record is the seed record | L14: =IF(K14="","",IF(K14=G14,"Y","N"))
A15: 10 | B15: pmid:37009773 | C15: Organoid intelligence (OI): the ultimate functionality of a brain microphysiological system (ALTEX) | D15: 2023 | E15: Review/roadmap | F15: Q1 | G15: Include | H15: R | I15: =IF(H15="","",IFERROR(INDEX(Codes!$B$2:$B$30,MATCH(H15,Codes!$A$2:$A$30,0)),"")) -> Include: review or roadmap that makes explicit claims about such systems | L15: =IF(K15="","",IF(K15=G15,"Y","N"))
A16: 11 | B16: pmid:38252094 | C16: The Promise and Potential of Brain Organoids | D16: 2024 | E16: Review/roadmap | F16: Q1 | G16: Maybe | H16: M | I16: =IF(H16="","",IFERROR(INDEX(Codes!$B$2:$B$30,MATCH(H16,Codes!$A$2:$A$30,0)),"")) -> Maybe: borderline, needs second screener or full-text check | J16: OI appears to be one section; check for explicit OI performance claims | L16: =IF(K16="","",IF(K16=G16,"Y","N"))
A17: 12 | B17: pmid:40540969 | C17: Scalable 3D packaging technique for brain organoid arrays toward high-capacity bioprocessors | D17: 2025 | E17: Engineering/tools | F17: Q1; Q2 | G17: Maybe | H17: M | I17: =IF(H17="","",IFERROR(INDEX(Codes!$B$2:$B$30,MATCH(H17,Codes!$A$2:$A$30,0)),"")) -> Maybe: borderline, needs second screener or full-text check | J17: Abstract asserts energy-efficient signal processing; check whether measured or motivational | L17: =IF(K17="","",IF(K17=G17,"Y","N"))
A18: 13 | B18: doi:10.64898/2026.10.11.758231 | C18: PULSE: foundation model for brain organoid network dynamics reporting intrinsic computation | D18: 2026 | E18: Empirical | F18: Q1 | G18: Include | H18: I | I18: =IF(H18="","",IFERROR(INDEX(Codes!$B$2:$B$30,MATCH(H18,Codes!$A$2:$A$30,0)),"")) -> Include: empirical paper with a computational, learning, or efficiency claim about living neural tissue as a substrate | J18: Preprint | L18: =IF(K18="","",IF(K18=G18,"Y","N"))
A19: 14 | B19: pmcid:PMC10796793 | C19: Brain organoids and organoid intelligence from ethical, legal, and social points of view | D19: 2023 | E19: Ethics | F19: Q1; Q5 | G19: Context | H19: C3 | I19: =IF(H19="","",IFERROR(INDEX(Codes!$B$2:$B$30,MATCH(H19,Codes!$A$2:$A$30,0)),"")) -> Context: ethics or governance paper specific to organoid computing / OI (ethics arm, not scored on the main rubric) | J19: Ethics arm, OI-specific | L19: =IF(K19="","",IF(K19=G19,"Y","N"))
A20: 15 | B20: pmcid:PMC13039412 | C20: Ethical concerns about embodied brain organoids (biocomputers): public attitudes experiment | D20: 2026 | E20: Ethics | F20: Q1; Q5 | G20: Context | H20: C3 | I20: =IF(H20="","",IFERROR(INDEX(Codes!$B$2:$B$30,MATCH(H20,Codes!$A$2:$A$30,0)),"")) -> Context: ethics or governance paper specific to organoid computing / OI (ethics arm, not scored on the main rubric) | J20: Ethics arm, OI-specific | L20: =IF(K20="","",IF(K20=G20,"Y","N"))
A21: 16 | B21: pmcid:PMC11869974 | C21: Emerging brain organoids: 3D models to decipher, identify and revolutionize brain | D21: 2025 | E21: Review/roadmap | F21: Q1 | G21: Exclude | H21: E2 | I21: =IF(H21="","",IFERROR(INDEX(Codes!$B$2:$B$30,MATCH(H21,Codes!$A$2:$A$30,0)),"")) -> Exclude: mentions OI only in passing | J21: OI mentioned in passing | L21: =IF(K21="","",IF(K21=G21,"Y","N"))
A22: 17 | B22: pmid:36480938 | C22: Neuronal cultures playing Pong: first steps toward advanced screening and biological computing (Neuron preview) | D22: 2022 | E22: Commentary/news | F22: Q1; Q3 | G22: Context | H22: C2 | I22: =IF(H22="","",IFERROR(INDEX(Codes!$B$2:$B$30,MATCH(H22,Codes!$A$2:$A$30,0)),"")) -> Context: commentary, editorial, or press coverage (not scored; used to trace how claims propagate) | J22: Commentary on Kagan; use for claim-propagation tracing | L22: =IF(K22="","",IF(K22=G22,"Y","N"))
A23: 18 | B23: pmcid:PMC12796111 | C23: Artificial Intelligence Virtual Organoids (AIVOs) | D23: 2025 | E23: AI/hardware-only | F23: Q1 | G23: Exclude | H23: E5 | I23: =IF(H23="","",IFERROR(INDEX(Codes!$B$2:$B$30,MATCH(H23,Codes!$A$2:$A$30,0)),"")) -> Exclude: AI, simulation, or hardware only; no living neural substrate | J23: Digital twins, no living substrate | L23: =IF(K23="","",IF(K23=G23,"Y","N"))
A24: 19 | B24: pmcid:PMC11870477 | C24: Neuromodulation in neural organoids with shell MEAs (preprint) | D24: 2025 | E24: Engineering/tools | F24: Q1; Q2 | G24: Exclude | H24: E1 | I24: =IF(H24="","",IFERROR(INDEX(Codes!$B$2:$B$30,MATCH(H24,Codes!$A$2:$A$30,0)),"")) -> Exclude: no computational, learning, or efficiency claim (disease modeling, tools, engineering, theory) | J24: Interface characterization | L24: =IF(K24="","",IF(K24=G24,"Y","N"))
A25: 20 | B25: doi:10.64898/2026.09.09.750433 | C25: Information processing-like phenotype of human brain organoids | D25: 2026 | E25: Empirical | F25: Q1; Q2 | G25: Include | H25: I | I25: =IF(H25="","",IFERROR(INDEX(Codes!$B$2:$B$30,MATCH(H25,Codes!$A$2:$A$30,0)),"")) -> Include: empirical paper with a computational, learning, or efficiency claim about living neural tissue as a substrate | J25: Preprint | L25: =IF(K25="","",IF(K25=G25,"Y","N"))
A26: 21 | B26: pmcid:PMC11661084 | C26: Goal-directed learning in cortical organoids (Cell Rep) | D26: 2026 | E26: Empirical | F26: Q1; Q2; Q3 | G26: Include | H26: I | I26: =IF(H26="","",IFERROR(INDEX(Codes!$B$2:$B$30,MATCH(H26,Codes!$A$2:$A$30,0)),"")) -> Include: empirical paper with a computational, learning, or efficiency claim about living neural tissue as a substrate | J26: bioRxiv preprint doi:10.1101/2024.12.07.627350 is the same work | L26: =IF(K26="","",IF(K26=G26,"Y","N"))
A27: 22 | B27: pmcid:PMC10995847 | C27: Moral considerability of brain organoids from the perspective of computational architecture | D27: 2024 | E27: Ethics | F27: Q1 | G27: Context | H27: C3 | I27: =IF(H27="","",IFERROR(INDEX(Codes!$B$2:$B$30,MATCH(H27,Codes!$A$2:$A$30,0)),"")) -> Context: ethics or governance paper specific to organoid computing / OI (ethics arm, not scored on the main rubric) | J27: Ethics arm, OI-specific | L27: =IF(K27="","",IF(K27=G27,"Y","N"))
A28: 23 | B28: pmcid:PMC11429697 | C28: Human neural organoid microphysiological systems show building blocks for basic learning and memory (bioRxiv) | D28: 2024 | E28: Empirical | F28: Q1 | G28: Exclude | H28: E3 | I28: =IF(H28="","",IFERROR(INDEX(Codes!$B$2:$B$30,MATCH(H28,Codes!$A$2:$A$30,0)),"")) -> Exclude: duplicate or earlier version of an included record (version of record kept) | J28: Preprint of PMC12357958 | L28: =IF(K28="","",IF(K28=G28,"Y","N"))
A29: 24 | B29: pmcid:PMC11027187 | C29: Organoid intelligence: integration of organoid technology and AI in the new era of in vitro models | D29: 2024 | E29: Review/roadmap | F29: Q1 | G29: Include | H29: R | I29: =IF(H29="","",IFERROR(INDEX(Codes!$B$2:$B$30,MATCH(H29,Codes!$A$2:$A$30,0)),"")) -> Include: review or roadmap that makes explicit claims about such systems | L29: =IF(K29="","",IF(K29=G29,"Y","N"))
A30: 25 | B30: pmid:32833194 | C30: Review of AI applications and algorithms for brain organoid research | D30: 2020 | E30: Review/roadmap | F30: Q1 | G30: Exclude | H30: E5 | I30: =IF(H30="","",IFERROR(INDEX(Codes!$B$2:$B$30,MATCH(H30,Codes!$A$2:$A$30,0)),"")) -> Exclude: AI, simulation, or hardware only; no living neural substrate | J30: AI used to analyze organoids, not organoids as computers | L30: =IF(K30="","",IF(K30=G30,"Y","N"))
A31: 26 | B31: doi:10.1101/2025.03.02.641081 | C31: Modeling Organoid Population Electrophysiology Dynamics | D31: 2025 | E31: Empirical | F31: Q1 | G31: Exclude | H31: E1 | I31: =IF(H31="","",IFERROR(INDEX(Codes!$B$2:$B$30,MATCH(H31,Codes!$A$2:$A$30,0)),"")) -> Exclude: no computational, learning, or efficiency claim (disease modeling, tools, engineering, theory) | J31: Disease/toxicology modeling framing | L31: =IF(K31="","",IF(K31=G31,"Y","N"))
A32: 27 | B32: pmid:42675178 | C32: Organoid intelligence: a promising paradigm for autism spectrum disorder research | D32: 2026 | E32: Review/roadmap | F32: Q1 | G32: Maybe | H32: M | I32: =IF(H32="","",IFERROR(INDEX(Codes!$B$2:$B$30,MATCH(H32,Codes!$A$2:$A$30,0)),"")) -> Maybe: borderline, needs second screener or full-text check | J32: OI framed for disease research; check for explicit OI performance claims | L32: =IF(K32="","",IF(K32=G32,"Y","N"))
A33: 28 | B33: pmid:42285251 | C33: Convergence and innovative applications of cutting-edge biomedical technologies in brain organoid research | D33: 2026 | E33: Review/roadmap | F33: Q1 | G33: Exclude | H33: E1 | I33: =IF(H33="","",IFERROR(INDEX(Codes!$B$2:$B$30,MATCH(H33,Codes!$A$2:$A$30,0)),"")) -> Exclude: no computational, learning, or efficiency claim (disease modeling, tools, engineering, theory) | L33: =IF(K33="","",IF(K33=G33,"Y","N"))
A34: 29 | B34: pmid:37288491 | C34: Human brain organoids: moral concerns if they grow up in the lab and are transplanted or destroyed | D34: 2023 | E34: Ethics | F34: Q1; Q5 | G34: Exclude | H34: E8 | I34: =IF(H34="","",IFERROR(INDEX(Codes!$B$2:$B$30,MATCH(H34,Codes!$A$2:$A$30,0)),"")) -> Exclude: brain-organoid ethics not specific to computing / OI | L34: =IF(K34="","",IF(K34=G34,"Y","N"))
A35: 30 | B35: pmcid:PMC11493634 | C35: Organoid intelligence for developmental neurotoxicity testing | D35: 2024 | E35: Review/roadmap | F35: Q1; Q2 | G35: Maybe | H35: M | I35: =IF(H35="","",IFERROR(INDEX(Codes!$B$2:$B$30,MATCH(H35,Codes!$A$2:$A$30,0)),"")) -> Maybe: borderline, needs second screener or full-text check | J35: Proposal paper; check for explicit OI capability claims | L35: =IF(K35="","",IF(K35=G35,"Y","N"))
A36: 31 | B36: pmid:41832075 | C36: Next-generation discovery: empowering organoid research with ML, AI and mathematical modeling | D36: 2026 | E36: Review/roadmap | F36: Q1 | G36: Exclude | H36: E5 | I36: =IF(H36="","",IFERROR(INDEX(Codes!$B$2:$B$30,MATCH(H36,Codes!$A$2:$A$30,0)),"")) -> Exclude: AI, simulation, or hardware only; no living neural substrate | L36: =IF(K36="","",IF(K36=G36,"Y","N"))
A37: 32 | B37: pmid:37496118 | C37: Brain Model Technology and Its Implications | D37: 2023 | E37: Ethics | F37: Q1 | G37: Exclude | H37: E8 | I37: =IF(H37="","",IFERROR(INDEX(Codes!$B$2:$B$30,MATCH(H37,Codes!$A$2:$A$30,0)),"")) -> Exclude: brain-organoid ethics not specific to computing / OI | L37: =IF(K37="","",IF(K37=G37,"Y","N"))
A38: 33 | B38: pmcid:PMC9338020 | C38: Human brain organoid networks (Nat Commun) | D38: 2022 | E38: Empirical | F38: Q1; Q2 | G38: Exclude | H38: E1 | I38: =IF(H38="","",IFERROR(INDEX(Codes!$B$2:$B$30,MATCH(H38,Codes!$A$2:$A$30,0)),"")) -> Exclude: no computational, learning, or efficiency claim (disease modeling, tools, engineering, theory) | J38: Network physiology; no computational claim in abstract | L38: =IF(K38="","",IF(K38=G38,"Y","N"))
A39: 34 | B39: doi:10.1101/2024.12.23.630065 | C39: Engineered biological neural networks as basic logic operators (bioRxiv) | D39: 2024 | E39: Empirical | F39: Q1 | G39: Exclude | H39: E3 | I39: =IF(H39="","",IFERROR(INDEX(Codes!$B$2:$B$30,MATCH(H39,Codes!$A$2:$A$30,0)),"")) -> Exclude: duplicate or earlier version of an included record (version of record kept) | J39: Preprint of PMC12066566 | L39: =IF(K39="","",IF(K39=G39,"Y","N"))
A40: 35 | B40: doi:10.64898/2026.10.02.756317 | C40: Flexible 3D multimodal organoid interface reveals functional subnetworks in cortical organoids | D40: 2026 | E40: Engineering/tools | F40: Q1; Q2 | G40: Exclude | H40: E1 | I40: =IF(H40="","",IFERROR(INDEX(Codes!$B$2:$B$30,MATCH(H40,Codes!$A$2:$A$30,0)),"")) -> Exclude: no computational, learning, or efficiency claim (disease modeling, tools, engineering, theory) | L40: =IF(K40="","",IF(K40=G40,"Y","N"))
A41: 36 | B41: pmcid:PMC13247413 | C41: BrAIn: AI-based morphology analysis system for brain organoids | D41: 2025 | E41: AI/hardware-only | F41: Q1 | G41: Exclude | H41: E5 | I41: =IF(H41="","",IFERROR(INDEX(Codes!$B$2:$B$30,MATCH(H41,Codes!$A$2:$A$30,0)),"")) -> Exclude: AI, simulation, or hardware only; no living neural substrate | L41: =IF(K41="","",IF(K41=G41,"Y","N"))
...

Sheet Flow
A1: Selection flow (PRISMA-style counts, auto-calculated from Screening_Log)
A3: Stage | B3: Count | C3: Note
A4: Unique records logged (de-duplicated by identifier) | B4: =COUNTA(Screening_Log!$B$6:$B$405) -> 190 | C4: 8 paper-index queries, 1 web query, 2 manual adds (see Protocol)
A5: Duplicates / earlier versions removed (E3) | B5: =COUNTIF(Screening_Log!$H$6:$H$405,"E3") -> 11 | C5: Preprints and arXiv versions of an included paper
A6: Records screened on title/abstract | B6: =B4-B5 -> 179
A7: Excluded E1: no computational/learning/efficiency claim | B7: =COUNTIF(Screening_Log!$H$6:$H$405,"E1") -> 34 | C7: Disease modeling, tools, engineering
A8: Excluded E2: OI mentioned in passing | B8: =COUNTIF(Screening_Log!$H$6:$H$405,"E2") -> 2
A9: Excluded E4: opinion, news, social, tertiary | B9: =COUNTIF(Screening_Log!$H$6:$H$405,"E4") -> 5
A10: Excluded E5: AI, simulation, or hardware only | B10: =COUNTIF(Screening_Log!$H$6:$H$405,"E5") -> 47 | C10: No living neural substrate
A11: Excluded E6: outside date range | B11: =COUNTIF(Screening_Log!$H$6:$H$405,"E6") -> 1
A12: Excluded E7: full text not accessible | B12: =COUNTIF(Screening_Log!$H$6:$H$405,"E7") -> 0
A13: Excluded E8: ethics not specific to computing/OI | B13: =COUNTIF(Screening_Log!$H$6:$H$405,"E8") -> 24 | C13: Candidates for ethics background if the team wants them
A14: Total excluded (excluding duplicates) | B14: =SUM(B7:B13) -> 113
A15: Context sources kept, not scored | B15: =COUNTIF(Screening_Log!$G$6:$G$405,"Context") -> 20
A16: C1 critique / skeptical | B16: =COUNTIF(Screening_Log!$H$6:$H$405,"C1") -> 2
A17: C2 commentary / press (claim propagation) | B17: =COUNTIF(Screening_Log!$H$6:$H$405,"C2") -> 6
A18: C3 ethics arm (OI-specific) | B18: =COUNTIF(Screening_Log!$H$6:$H$405,"C3") -> 9
A19: C4 comparator literature | B19: =COUNTIF(Screening_Log!$H$6:$H$405,"C4") -> 3
A20: Maybe: needs second screener | B20: =COUNTIF(Screening_Log!$G$6:$G$405,"Maybe") -> 5 | C20: Promote to Include or exclude after full-text check
A21: Included for scoring | B21: =COUNTIF(Screening_Log!$G$6:$G$405,"Include") -> 41 | C21: Rows are pre-filled on the Scoring sheet
A22: Empirical (I) | B22: =COUNTIF(Screening_Log!$H$6:$H$405,"I") -> 28
A23: Review / roadmap (R) | B23: =COUNTIF(Screening_Log!$H$6:$H$405,"R") -> 10
A24: Grey literature (G) | B24: =COUNTIF(Screening_Log!$H$6:$H$405,"G") -> 3
A25: Check: screened - excluded - context - maybe - included | B25: =B6-B14-B15-B20-B21 -> 0 | C25: Should be 0
A26: Check status | B26: =IF(B25=0,"OK","CHECK") -> OK
A27: Second-screener sample size | B27: =COUNTA(Screening_Log!$K$6:$K$405) -> 0 | C27: Aim for ~20% of screened records
A28: Second-screener agreement | B28: =IF(B27=0,"",COUNTIF(Screening_Log!$L$6:$L$405,"Y")/B27) | C28: Share of sampled records where decision matches

Sheet Claims
A1: Claims audit: one row per claim
A2: Rows C01-C11 are copied from the team's OI Notes on the five seed papers (source column says so); they were not re-checked against the PDFs. Add one row per claim as you code each paper. Tags: Demonstrated, Demonstrated under constraints, Projected (extrapolated estimate), Illustrative (authors flag it as illustration), Aspirational (stated as a future goal), Not demonstrated.
A4: Claim ID | B4: Paper ID | C4: Paper | D4: Category | E4: Claim | F4: Claim tag | G4: Evidence basis | H4: Comparator | I4: Unit / n | J4: Source | K4: Notes (where in paper, caveats)
A5: C01 | B5: doi:10.1016/j.neuron.2022.09.001 | C5: Kagan 2022 | D5: Learning/adaptation | E5: Learning in 2D cortical cultures with closed-loop feedback (Pong) | F5: Demonstrated under constraints | G5: Measured | H5: No-cell, rest, in-silico, HEK293T and media-only controls (none showed learning) | I5: Cultures: MCC 9, HCC 11; sessions 101 and 138 (not independent) | J5: Team OI Notes | K5: Not robust across days (cultures appeared to relearn each session); 2D monolayers, not organoids. Resolve n (cultures vs sessions) in Figure 5 legend and Methods.
A6: C02 | B6: doi:10.1016/j.neuron.2022.09.001 | C6: Kagan 2022 | D6: Sentience/intelligence | E6: 'Sentience' (responsive to sensory impressions) | F6: Not demonstrated | J6: Team OI Notes | K6: Team notes: very weak definition, so the title overstates the result. Coder to confirm the tag.
A7: C03 | B7: doi:10.1038/s41928-023-01069-w | C7: Cai 2023 | D7: Computational performance | E7: Henon-map prediction improves with training in organoids (about 0.36 on day 1 to about 0.81 after four epochs) | F7: Demonstrated under constraints | G7: Measured | H7: Linear regression; ANN with/without LSTM (about 50 epochs). Baseline strength unverified; fair check is a software reservoir of similar size | I7: Not recorded; verify | J7: Team OI Notes | K7: Negative control (K252a) about 0.31 to 0.39; blank chip 0. Authors list organoid heterogeneity and variable viability as limits.
A8: C04 | B8: doi:10.1038/s41928-023-01069-w | C8: Cai 2023 | D8: Efficiency (energy/sample/cost) | E8: Energy advantage of brain over AI hardware (about 20 W vs about 8 MW) | F8: Not demonstrated | G8: None | J8: Team OI Notes | K8: Motivation only (Introduction/Discussion); no energy measured for Brainoware.
A9: C05 | B9: doi:10.34133/cbsystems.0336 | C9: Khajehnejad 2025 | D9: Efficiency (energy/sample/cost) | E9: Sample efficiency of cultures versus DQN, A2C and PPO | F9: Demonstrated under constraints | G9: Measured | H9: DQN, A2C, PPO. RL got 40x40 pixels vs cultures' 8-pixel input; 70-episode cap mapped to about 20 minutes | I9: HCC 174 sessions, MCC 110 sessions | J9: Team OI Notes | K9: With 11,000 episodes all three RL algorithms learned. Hypothesis stated up front. Cortical Labs co-authors. Authors call energy comparison 'difficult'.
A10: C06 | B10: doi:10.3389/frai.2024.1376042 | C10: Jordan 2024 | D10: Other | E10: Platform infrastructure: organoids maintained and stimulated remotely; lifespan up to 100 days in best cases | F10: Demonstrated | G10: Measured | I10: Over 1,000 organoids over three years (per team notes) | J10: Team OI Notes | K10: Section labels for lifespan and capacity limits were inferred in the notes; confirm in the PDF.
A11: C07 | B11: doi:10.3389/frai.2024.1376042 | C11: Jordan 2024 | D11: Efficiency (energy/sample/cost) | E11: Energy efficiency of wetware versus silicon | F11: Projected | G11: Projected | H11: GPT-3 training energy vs 20 W brain (motivation) | J11: Team OI Notes | K11: No measured energy or power figures. A fair comparison must count two incubators, a peristaltic pump, a syringe pump and cameras per MEA.
A12: C08 | B12: doi:10.3389/frai.2024.1376042 | C12: Jordan 2024 | D12: Computational performance | E12: Computing performance / classification accuracy | F12: Not demonstrated | G12: None | J12: Team OI Notes | K12: Team notes: work shown is stimulation experiments, not a computing benchmark. Do not cite the 95.5% figure as accuracy; it came from an extraction tool, verify in Section 5.2.
A13: C09 | B13: doi:10.3389/fsci.2023.1017235 | C13: Smirnova 2023 | D13: Efficiency (energy/sample/cost) | E13: Brain-vs-machine efficiency numbers (Frontier 21 MW vs brain 10-20 W; about 10^10x energy; >10^6x data efficiency) | F13: Illustrative | G13: Cited from other work | H13: Frontier supercomputer; AlphaGo | J13: Team OI Notes | K13: Whole-brain figures, not organoid. Authors say comparisons 'serve only as illustrations' and OI power demands are 'very different'.
A14: C10 | B14: doi:10.3389/fsci.2023.1017235 | C14: Smirnova 2023 | D14: Computational performance | E14: Per-organoid capacity (about 800 MB) and OI performance potential | F14: Aspirational | G14: Projected | J14: Team OI Notes | K14: Theoretical, based on under 500 um diameter and under 100,000 cells. Authors say most biocomputing research 'remains in its infancy'.
A15: C11 | B15: doi:10.3389/fsci.2023.1017235 | C15: Smirnova 2023 | D15: Learning/adaptation | E15: Learning in cultures cited as support for OI | F15: Demonstrated | G15: Cited from other work | J15: Team OI Notes | K15: Team notes: demonstrated elsewhere (Kagan), in 2D cultures only; not organoid evidence.

Sheet Scoring
A1: Scoring sheet: one row per included paper
A2: Score each item 0/1/2 or NA (see Rubric_Anchors). Rater 1 and Rater 2 score independently without seeing each other's columns; the Final block shows the agreed score, or DISCUSS where raters differ. After discussion, overwrite DISCUSS cells with the agreed value.
A3: Blue-on-yellow = team input. Columns E and F are pre-filled drafts (from abstracts and identifiers) and need checking; COI for the five seed papers comes from the team's OI Notes. Always verify scores against the PDF, not the abstract.
A4: Paper (pre-filled) | J4: Rater 1 | S4: Rater 2 | AB4: Final (auto: R1/R2 match, else DISCUSS) | AK4: Summary and tier | AP4: Notes
A5: Paper ID | B5: Paper | C5: Year | D5: Type | E5: Claim categories (draft: C=computational, L=learning, E=efficiency) | F5: Peer-review status (auto from identifier) | G5: COI / affiliation | H5: Replication evidence (cite who/where; informs RP score) | I5: Hypothesis stated up front | J5: R1 SM | K5: R1 UA | L5: R1 CT | M5: R1 CF | N5: R1 EA | O5: R1 RB | P5: R1 TR | Q5: R1 CC | R5: R1 RP | S5: R2 SM | T5: R2 UA | U5: R2 CT | V5: R2 CF | W5: R2 EA | X5: R2 RB | Y5: R2 TR | Z5: R2 CC | AA5: R2 RP | AB5: Final SM | AC5: Final UA | AD5: Final CT | AE5: Final CF | AF5: Final EA | AG5: Final RB | AH5: Final TR | AI5: Final CC | AJ5: Final RP | AK5: Final mean | AL5: Items scored | AM5: Items to discuss | AN5: Tier (auto) | AO5: Rank within tier | AP5: Notes
A6: doi:10.1016/j.neuron.2022.09.001 | B6: Kagan et al. In vitro neurons learn and exhibit sentience when embodied in a simulated game-world (DishBrain), Neuron | C6: 2022 | D6: Empirical | E6: L | F6: Peer-reviewed | G6: Mixed academic-industry authors | I6: Unknown | AB6: =IF(J6="","",IF(S6="",J6,IF(J6=S6,J6,"DISCUSS"))) | AC6: =IF(K6="","",IF(T6="",K6,IF(K6=T6,K6,"DISCUSS"))) | AD6: =IF(L6="","",IF(U6="",L6,IF(L6=U6,L6,"DISCUSS"))) | AE6: =IF(M6="","",IF(V6="",M6,IF(M6=V6,M6,"DISCUSS"))) | AF6: =IF(N6="","",IF(W6="",N6,IF(N6=W6,N6,"DISCUSS"))) | AG6: =IF(O6="","",IF(X6="",O6,IF(O6=X6,O6,"DISCUSS"))) | AH6: =IF(P6="","",IF(Y6="",P6,IF(P6=Y6,P6,"DISCUSS"))) | AI6: =IF(Q6="","",IF(Z6="",Q6,IF(Q6=Z6,Q6,"DISCUSS"))) | AJ6: =IF(R6="","",IF(AA6="",R6,IF(R6=AA6,R6,"DISCUSS"))) | AK6: =IFERROR(AVERAGE(AB6:AJ6),"") | AL6: =COUNT(AB6:AJ6) -> 0 | AM6: =COUNTIF(AB6:AJ6,"DISCUSS") -> 0 | AN6: =IF(AL6=0,"",IF(AM6>0,"Resolve DISCUSS",IF(AL6<Tiers!$B$6,"Unrated",IF(AK6>=Tiers!$B$4,"High",IF(AK6>=Tiers!$B$5,"Medium","Low"))))) | AO6: =IF(OR(AN6="",AN6="Unrated",AN6="Resolve DISCUSS"),"",COUNTIFS($AN$6:$AN$105,AN6,$AK$6:$AK$105,">"&AK6)+1)
A7: doi:10.1038/s41928-023-01069-w | B7: Cai et al. Brain organoid reservoir computing for artificial intelligence (Brainoware), Nat Electron | C7: 2023 | D7: Empirical | E7: C,E | F7: Peer-reviewed | G7: Academic, none declared | I7: Unknown | AB7: =IF(J7="","",IF(S7="",J7,IF(J7=S7,J7,"DISCUSS"))) | AC7: =IF(K7="","",IF(T7="",K7,IF(K7=T7,K7,"DISCUSS"))) | AD7: =IF(L7="","",IF(U7="",L7,IF(L7=U7,L7,"DISCUSS"))) | AE7: =IF(M7="","",IF(V7="",M7,IF(M7=V7,M7,"DISCUSS"))) | AF7: =IF(N7="","",IF(W7="",N7,IF(N7=W7,N7,"DISCUSS"))) | AG7: =IF(O7="","",IF(X7="",O7,IF(O7=X7,O7,"DISCUSS"))) | AH7: =IF(P7="","",IF(Y7="",P7,IF(P7=Y7,P7,"DISCUSS"))) | AI7: =IF(Q7="","",IF(Z7="",Q7,IF(Q7=Z7,Q7,"DISCUSS"))) | AJ7: =IF(R7="","",IF(AA7="",R7,IF(R7=AA7,R7,"DISCUSS"))) | AK7: =IFERROR(AVERAGE(AB7:AJ7),"") | AL7: =COUNT(AB7:AJ7) -> 0 | AM7: =COUNTIF(AB7:AJ7,"DISCUSS") -> 0 | AN7: =IF(AL7=0,"",IF(AM7>0,"Resolve DISCUSS",IF(AL7<Tiers!$B$6,"Unrated",IF(AK7>=Tiers!$B$4,"High",IF(AK7>=Tiers!$B$5,"Medium","Low"))))) | AO7: =IF(OR(AN7="",AN7="Unrated",AN7="Resolve DISCUSS"),"",COUNTIFS($AN$6:$AN$105,AN7,$AK$6:$AK$105,">"&AK7)+1)
A8: doi:10.34133/cbsystems.0336 | B8: Khajehnejad et al. Dynamic network plasticity and sample efficiency in biological neural cultures: comparison with deep RL, Cyborg Bionic Syst | C8: 2025 | D8: Empirical | E8: L,E | F8: Peer-reviewed | G8: Mixed academic-industry authors | I8: Unknown | AB8: =IF(J8="","",IF(S8="",J8,IF(J8=S8,J8,"DISCUSS"))) | AC8: =IF(K8="","",IF(T8="",K8,IF(K8=T8,K8,"DISCUSS"))) | AD8: =IF(L8="","",IF(U8="",L8,IF(L8=U8,L8,"DISCUSS"))) | AE8: =IF(M8="","",IF(V8="",M8,IF(M8=V8,M8,"DISCUSS"))) | AF8: =IF(N8="","",IF(W8="",N8,IF(N8=W8,N8,"DISCUSS"))) | AG8: =IF(O8="","",IF(X8="",O8,IF(O8=X8,O8,"DISCUSS"))) | AH8: =IF(P8="","",IF(Y8="",P8,IF(P8=Y8,P8,"DISCUSS"))) | AI8: =IF(Q8="","",IF(Z8="",Q8,IF(Q8=Z8,Q8,"DISCUSS"))) | AJ8: =IF(R8="","",IF(AA8="",R8,IF(R8=AA8,R8,"DISCUSS"))) | AK8: =IFERROR(AVERAGE(AB8:AJ8),"") | AL8: =COUNT(AB8:AJ8) -> 0 | AM8: =COUNTIF(AB8:AJ8,"DISCUSS") -> 0 | AN8: =IF(AL8=0,"",IF(AM8>0,"Resolve DISCUSS",IF(AL8<Tiers!$B$6,"Unrated",IF(AK8>=Tiers!$B$4,"High",IF(AK8>=Tiers!$B$5,"Medium","Low"))))) | AO8: =IF(OR(AN8="",AN8="Unrated",AN8="Resolve DISCUSS"),"",COUNTIFS($AN$6:$AN$105,AN8,$AK$6:$AK$105,">"&AK8)+1)
A9: doi:10.3389/frai.2024.1376042 | B9: Jordan et al. Open and remotely accessible Neuroplatform for research in wetware computing (FinalSpark), Front AI | C9: 2024 | D9: Empirical | E9: C,E | F9: Peer-reviewed | G9: Company / industry source | I9: Unknown | AB9: =IF(J9="","",IF(S9="",J9,IF(J9=S9,J9,"DISCUSS"))) | AC9: =IF(K9="","",IF(T9="",K9,IF(K9=T9,K9,"DISCUSS"))) | AD9: =IF(L9="","",IF(U9="",L9,IF(L9=U9,L9,"DISCUSS"))) | AE9: =IF(M9="","",IF(V9="",M9,IF(M9=V9,M9,"DISCUSS"))) | AF9: =IF(N9="","",IF(W9="",N9,IF(N9=W9,N9,"DISCUSS"))) | AG9: =IF(O9="","",IF(X9="",O9,IF(O9=X9,O9,"DISCUSS"))) | AH9: =IF(P9="","",IF(Y9="",P9,IF(P9=Y9,P9,"DISCUSS"))) | AI9: =IF(Q9="","",IF(Z9="",Q9,IF(Q9=Z9,Q9,"DISCUSS"))) | AJ9: =IF(R9="","",IF(AA9="",R9,IF(R9=AA9,R9,"DISCUSS"))) | AK9: =IFERROR(AVERAGE(AB9:AJ9),"") | AL9: =COUNT(AB9:AJ9) -> 0 | AM9: =COUNTIF(AB9:AJ9,"DISCUSS") -> 0 | AN9: =IF(AL9=0,"",IF(AM9>0,"Resolve DISCUSS",IF(AL9<Tiers!$B$6,"Unrated",IF(AK9>=Tiers!$B$4,"High",IF(AK9>=Tiers!$B$5,"Medium","Low"))))) | AO9: =IF(OR(AN9="",AN9="Unrated",AN9="Resolve DISCUSS"),"",COUNTIFS($AN$6:$AN$105,AN9,$AK$6:$AK$105,">"&AK9)+1)
A10: doi:10.64898/2026.10.11.758231 | B10: PULSE: foundation model for brain organoid network dynamics reporting intrinsic computation | C10: 2026 | D10: Empirical | E10: C | F10: Preprint | G10: Not checked | I10: Unknown | AB10: =IF(J10="","",IF(S10="",J10,IF(J10=S10,J10,"DISCUSS"))) | AC10: =IF(K10="","",IF(T10="",K10,IF(K10=T10,K10,"DISCUSS"))) | AD10: =IF(L10="","",IF(U10="",L10,IF(L10=U10,L10,"DISCUSS"))) | AE10: =IF(M10="","",IF(V10="",M10,IF(M10=V10,M10,"DISCUSS"))) | AF10: =IF(N10="","",IF(W10="",N10,IF(N10=W10,N10,"DISCUSS"))) | AG10: =IF(O10="","",IF(X10="",O10,IF(O10=X10,O10,"DISCUSS"))) | AH10: =IF(P10="","",IF(Y10="",P10,IF(P10=Y10,P10,"DISCUSS"))) | AI10: =IF(Q10="","",IF(Z10="",Q10,IF(Q10=Z10,Q10,"DISCUSS"))) | AJ10: =IF(R10="","",IF(AA10="",R10,IF(R10=AA10,R10,"DISCUSS"))) | AK10: =IFERROR(AVERAGE(AB10:AJ10),"") | AL10: =COUNT(AB10:AJ10) -> 0 | AM10: =COUNTIF(AB10:AJ10,"DISCUSS") -> 0 | AN10: =IF(AL10=0,"",IF(AM10>0,"Resolve DISCUSS",IF(AL10<Tiers!$B$6,"Unrated",IF(AK10>=Tiers!$B$4,"High",IF(AK10>=Tiers!$B$5,"Medium","Low"))))) | AO10: =IF(OR(AN10="",AN10="Unrated",AN10="Resolve DISCUSS"),"",COUNTIFS($AN$6:$AN$105,AN10,$AK$6:$AK$105,">"&AK10)+1)
A11: doi:10.64898/2026.09.09.750433 | B11: Information processing-like phenotype of human brain organoids | C11: 2026 | D11: Empirical | E11: C | F11: Preprint | G11: Not checked | I11: Unknown | AB11: =IF(J11="","",IF(S11="",J11,IF(J11=S11,J11,"DISCUSS"))) | AC11: =IF(K11="","",IF(T11="",K11,IF(K11=T11,K11,"DISCUSS"))) | AD11: =IF(L11="","",IF(U11="",L11,IF(L11=U11,L11,"DISCUSS"))) | AE11: =IF(M11="","",IF(V11="",M11,IF(M11=V11,M11,"DISCUSS"))) | AF11: =IF(N11="","",IF(W11="",N11,IF(N11=W11,N11,"DISCUSS"))) | AG11: =IF(O11="","",IF(X11="",O11,IF(O11=X11,O11,"DISCUSS"))) | AH11: =IF(P11="","",IF(Y11="",P11,IF(P11=Y11,P11,"DISCUSS"))) | AI11: =IF(Q11="","",IF(Z11="",Q11,IF(Q11=Z11,Q11,"DISCUSS"))) | AJ11: =IF(R11="","",IF(AA11="",R11,IF(R11=AA11,R11,"DISCUSS"))) | AK11: =IFERROR(AVERAGE(AB11:AJ11),"") | AL11: =COUNT(AB11:AJ11) -> 0 | AM11: =COUNTIF(AB11:AJ11,"DISCUSS") -> 0 | AN11: =IF(AL11=0,"",IF(AM11>0,"Resolve DISCUSS",IF(AL11<Tiers!$B$6,"Unrated",IF(AK11>=Tiers!$B$4,"High",IF(AK11>=Tiers!$B$5,"Medium","Low"))))) | AO11: =IF(OR(AN11="",AN11="Unrated",AN11="Resolve DISCUSS"),"",COUNTIFS($AN$6:$AN$105,AN11,$AK$6:$AK$105,">"&AK11)+1)
A12: pmcid:PMC11661084 | B12: Goal-directed learning in cortical organoids (Cell Rep) | C12: 2026 | D12: Empirical | E12: L | F12: Peer-reviewed | G12: Not checked | I12: Unknown | AB12: =IF(J12="","",IF(S12="",J12,IF(J12=S12,J12,"DISCUSS"))) | AC12: =IF(K12="","",IF(T12="",K12,IF(K12=T12,K12,"DISCUSS"))) | AD12: =IF(L12="","",IF(U12="",L12,IF(L12=U12,L12,"DISCUSS"))) | AE12: =IF(M12="","",IF(V12="",M12,IF(M12=V12,M12,"DISCUSS"))) | AF12: =IF(N12="","",IF(W12="",N12,IF(N12=W12,N12,"DISCUSS"))) | AG12: =IF(O12="","",IF(X12="",O12,IF(O12=X12,O12,"DISCUSS"))) | AH12: =IF(P12="","",IF(Y12="",P12,IF(P12=Y12,P12,"DISCUSS"))) | AI12: =IF(Q12="","",IF(Z12="",Q12,IF(Q12=Z12,Q12,"DISCUSS"))) | AJ12: =IF(R12="","",IF(AA12="",R12,IF(R12=AA12,R12,"DISCUSS"))) | AK12: =IFERROR(AVERAGE(AB12:AJ12),"") | AL12: =COUNT(AB12:AJ12) -> 0 | AM12: =COUNTIF(AB12:AJ12,"DISCUSS") -> 0 | AN12: =IF(AL12=0,"",IF(AM12>0,"Resolve DISCUSS",IF(AL12<Tiers!$B$6,"Unrated",IF(AK12>=Tiers!$B$4,"High",IF(AK12>=Tiers!$B$5,"Medium","Low"))))) | AO12: =IF(OR(AN12="",AN12="Unrated",AN12="Resolve DISCUSS"),"",COUNTIFS($AN$6:$AN$105,AN12,$AK$6:$AK$105,">"&AK12)+1)
A13: pmcid:PMC12357958 | B13: Human neural organoid microphysiological systems show building blocks for basic learning and memory (Commun Biol) | C13: 2025 | D13: Empirical | E13: L | F13: Peer-reviewed | G13: Not checked | I13: Unknown | AB13: =IF(J13="","",IF(S13="",J13,IF(J13=S13,J13,"DISCUSS"))) | AC13: =IF(K13="","",IF(T13="",K13,IF(K13=T13,K13,"DISCUSS"))) | AD13: =IF(L13="","",IF(U13="",L13,IF(L13=U13,L13,"DISCUSS"))) | AE13: =IF(M13="","",IF(V13="",M13,IF(M13=V13,M13,"DISCUSS"))) | AF13: =IF(N13="","",IF(W13="",N13,IF(N13=W13,N13,"DISCUSS"))) | AG13: =IF(O13="","",IF(X13="",O13,IF(O13=X13,O13,"DISCUSS"))) | AH13: =IF(P13="","",IF(Y13="",P13,IF(P13=Y13,P13,"DISCUSS"))) | AI13: =IF(Q13="","",IF(Z13="",Q13,IF(Q13=Z13,Q13,"DISCUSS"))) | AJ13: =IF(R13="","",IF(AA13="",R13,IF(R13=AA13,R13,"DISCUSS"))) | AK13: =IFERROR(AVERAGE(AB13:AJ13),"") | AL13: =COUNT(AB13:AJ13) -> 0 | AM13: =COUNTIF(AB13:AJ13,"DISCUSS") -> 0 | AN13: =IF(AL13=0,"",IF(AM13>0,"Resolve DISCUSS",IF(AL13<Tiers!$B$6,"Unrated",IF(AK13>=Tiers!$B$4,"High",IF(AK13>=Tiers!$B$5,"Medium","Low"))))) | AO13: =IF(OR(AN13="",AN13="Unrated",AN13="Resolve DISCUSS"),"",COUNTIFS($AN$6:$AN$105,AN13,$AK$6:$AK$105,">"&AK13)+1)
A14: pmcid:PMC12066566 | B14: Engineered biological neuronal networks as basic logic operators (Front Comput Neurosci) | C14: 2025 | D14: Empirical | E14: C | F14: Peer-reviewed | G14: Not checked | I14: Unknown | AB14: =IF(J14="","",IF(S14="",J14,IF(J14=S14,J14,"DISCUSS"))) | AC14: =IF(K14="","",IF(T14="",K14,IF(K14=T14,K14,"DISCUSS"))) | AD14: =IF(L14="","",IF(U14="",L14,IF(L14=U14,L14,"DISCUSS"))) | AE14: =IF(M14="","",IF(V14="",M14,IF(M14=V14,M14,"DISCUSS"))) | AF14: =IF(N14="","",IF(W14="",N14,IF(N14=W14,N14,"DISCUSS"))) | AG14: =IF(O14="","",IF(X14="",O14,IF(O14=X14,O14,"DISCUSS"))) | AH14: =IF(P14="","",IF(Y14="",P14,IF(P14=Y14,P14,"DISCUSS"))) | AI14: =IF(Q14="","",IF(Z14="",Q14,IF(Q14=Z14,Q14,"DISCUSS"))) | AJ14: =IF(R14="","",IF(AA14="",R14,IF(R14=AA14,R14,"DISCUSS"))) | AK14: =IFERROR(AVERAGE(AB14:AJ14),"") | AL14: =COUNT(AB14:AJ14) -> 0 | AM14: =COUNTIF(AB14:AJ14,"DISCUSS") -> 0 | AN14: =IF(AL14=0,"",IF(AM14>0,"Resolve DISCUSS",IF(AL14<Tiers!$B$6,"Unrated",IF(AK14>=Tiers!$B$4,"High",IF(AK14>=Tiers!$B$5,"Medium","Low"))))) | AO14: =IF(OR(AN14="",AN14="Unrated",AN14="Resolve DISCUSS"),"",COUNTIFS($AN$6:$AN$105,AN14,$AK$6:$AK$105,">"&AK14)+1)
A15: doi:10.64898/2026.08.10.743829 | B15: Handwritten digit classification with neural cultures: architecture, dynamics, decoding | C15: 2026 | D15: Empirical | E15: C,E | F15: Preprint | G15: Not checked | I15: Unknown | AB15: =IF(J15="","",IF(S15="",J15,IF(J15=S15,J15,"DISCUSS"))) | AC15: =IF(K15="","",IF(T15="",K15,IF(K15=T15,K15,"DISCUSS"))) | AD15: =IF(L15="","",IF(U15="",L15,IF(L15=U15,L15,"DISCUSS"))) | AE15: =IF(M15="","",IF(V15="",M15,IF(M15=V15,M15,"DISCUSS"))) | AF15: =IF(N15="","",IF(W15="",N15,IF(N15=W15,N15,"DISCUSS"))) | AG15: =IF(O15="","",IF(X15="",O15,IF(O15=X15,O15,"DISCUSS"))) | AH15: =IF(P15="","",IF(Y15="",P15,IF(P15=Y15,P15,"DISCUSS"))) | AI15: =IF(Q15="","",IF(Z15="",Q15,IF(Q15=Z15,Q15,"DISCUSS"))) | AJ15: =IF(R15="","",IF(AA15="",R15,IF(R15=AA15,R15,"DISCUSS"))) | AK15: =IFERROR(AVERAGE(AB15:AJ15),"") | AL15: =COUNT(AB15:AJ15) -> 0 | AM15: =COUNTIF(AB15:AJ15,"DISCUSS") -> 0 | AN15: =IF(AL15=0,"",IF(AM15>0,"Resolve DISCUSS",IF(AL15<Tiers!$B$6,"Unrated",IF(AK15>=Tiers!$B$4,"High",IF(AK15>=Tiers!$B$5,"Medium","Low"))))) | AO15: =IF(OR(AN15="",AN15="Unrated",AN15="Resolve DISCUSS"),"",COUNTIFS($AN$6:$AN$105,AN15,$AK$6:$AK$105,">"&AK15)+1)
A16: arxiv:2602.05737 | B16: Neuro-inspired visual pattern recognition via biological reservoir computing | C16: 2026 | D16: Empirical | E16: C | F16: Preprint | G16: Not checked | I16: Unknown | AB16: =IF(J16="","",IF(S16="",J16,IF(J16=S16,J16,"DISCUSS"))) | AC16: =IF(K16="","",IF(T16="",K16,IF(K16=T16,K16,"DISCUSS"))) | AD16: =IF(L16="","",IF(U16="",L16,IF(L16=U16,L16,"DISCUSS"))) | AE16: =IF(M16="","",IF(V16="",M16,IF(M16=V16,M16,"DISCUSS"))) | AF16: =IF(N16="","",IF(W16="",N16,IF(N16=W16,N16,"DISCUSS"))) | AG16: =IF(O16="","",IF(X16="",O16,IF(O16=X16,O16,"DISCUSS"))) | AH16: =IF(P16="","",IF(Y16="",P16,IF(P16=Y16,P16,"DISCUSS"))) | AI16: =IF(Q16="","",IF(Z16="",Q16,IF(Q16=Z16,Q16,"DISCUSS"))) | AJ16: =IF(R16="","",IF(AA16="",R16,IF(R16=AA16,R16,"DISCUSS"))) | AK16: =IFERROR(AVERAGE(AB16:AJ16),"") | AL16: =COUNT(AB16:AJ16) -> 0 | AM16: =COUNTIF(AB16:AJ16,"DISCUSS") -> 0 | AN16: =IF(AL16=0,"",IF(AM16>0,"Resolve DISCUSS",IF(AL16<Tiers!$B$6,"Unrated",IF(AK16>=Tiers!$B$4,"High",IF(AK16>=Tiers!$B$5,"Medium","Low"))))) | AO16: =IF(OR(AN16="",AN16="Unrated",AN16="Resolve DISCUSS"),"",COUNTIFS($AN$6:$AN$105,AN16,$AK$6:$AK$105,">"&AK16)+1)
A17: arxiv:2505.03510 | B17: From neurons to computation: biological reservoir computing for pattern recognition | C17: 2025 | D17: Empirical | E17: C | F17: Preprint | G17: Not checked | I17: Unknown | AB17: =IF(J17="","",IF(S17="",J17,IF(J17=S17,J17,"DISCUSS"))) | AC17: =IF(K17="","",IF(T17="",K17,IF(K17=T17,K17,"DISCUSS"))) | AD17: =IF(L17="","",IF(U17="",L17,IF(L17=U17,L17,"DISCUSS"))) | AE17: =IF(M17="","",IF(V17="",M17,IF(M17=V17,M17,"DISCUSS"))) | AF17: =IF(N17="","",IF(W17="",N17,IF(N17=W17,N17,"DISCUSS"))) | AG17: =IF(O17="","",IF(X17="",O17,IF(O17=X17,O17,"DISCUSS"))) | AH17: =IF(P17="","",IF(Y17="",P17,IF(P17=Y17,P17,"DISCUSS"))) | AI17: =IF(Q17="","",IF(Z17="",Q17,IF(Q17=Z17,Q17,"DISCUSS"))) | AJ17: =IF(R17="","",IF(AA17="",R17,IF(R17=AA17,R17,"DISCUSS"))) | AK17: =IFERROR(AVERAGE(AB17:AJ17),"") | AL17: =COUNT(AB17:AJ17) -> 0 | AM17: =COUNTIF(AB17:AJ17,"DISCUSS") -> 0 | AN17: =IF(AL17=0,"",IF(AM17>0,"Resolve DISCUSS",IF(AL17<Tiers!$B$6,"Unrated",IF(AK17>=Tiers!$B$4,"High",IF(AK17>=Tiers!$B$5,"Medium","Low"))))) | AO17: =IF(OR(AN17="",AN17="Unrated",AN17="Resolve DISCUSS"),"",COUNTIFS($AN$6:$AN$105,AN17,$AK$6:$AK$105,">"&AK17)+1)
... A33: pmid:41983381 | B33: In vitro biological neuronal networks achieve low power consumption and high-speed communication through predictable stimulation | C33: 2026 | D33: Empirical | E33: E | F33: Peer-reviewed | G33: Not checked | I33: Unknown | AB33: =IF(J33="","",IF(S33="",J33,IF(J33=S33,J33,"DISCUSS"))) | AC33: =IF(K33="","",IF(T33="",K33,IF(K33=T33,K33,"DISCUSS"))) | AD33: =IF(L33="","",IF(U33="",L33,IF(L33=U33,L33,"DISCUSS"))) | AE33: =IF(M33="","",IF(V33="",M33,IF(M33=V33,M33,"DISCUSS"))) | AF33: =IF(N33="","",IF(W33="",N33,IF(N33=W33,N33,"DISCUSS"))) | AG33: =IF(O33="","",IF(X33="",O33,IF(O33=X33,O33,"DISCUSS"))) | AH33: =IF(P33="","",IF(Y33="",P33,IF(P33=Y33,P33,"DISCUSS"))) | AI33: =IF(Q33="","",IF(Z33="",Q33,IF(Q33=Z33,Q33,"DISCUSS"))) | AJ33: =IF(R33="","",IF(AA33="",R33,IF(R33=AA33,R33,"DISCUSS"))) | AK33: =IFERROR(AVERAGE(AB33:AJ33),"") | AL33: =COUNT(AB33:AJ33) -> 0 | AM33: =COUNTIF(AB33:AJ33,"DISCUSS") -> 0 | AN33: =IF(AL33=0,"",IF(AM33>0,"Resolve DISCUSS",IF(AL33<Tiers!$B$6,"Unrated",IF(AK33>=Tiers!$B$4,"High",IF(AK33>=Tiers!$B$5,"Medium","Low"))))) | AO33: =IF(OR(AN33="",AN33="Unrated",AN33="Resolve DISCUSS"),"",COUNTIFS($AN$6:$AN$105,AN33,$AK$6:$AK$105,">"&AK33)+1)
AB34: =IF(J34="","",IF(S34="",J34,IF(J34=S34,J34,"DISCUSS"))) | AC34: =IF(K34="","",IF(T34="",K34,IF(K34=T34,K34,"DISCUSS"))) | AD34: =IF(L34="","",IF(U34="",L34,IF(L34=U34,L34,"DISCUSS"))) | AE34: =IF(M34="","",IF(V34="",M34,IF(M34=V34,M34,"DISCUSS"))) | AF34: =IF(N34="","",IF(W34="",N34,IF(N34=W34,N34,"DISCUSS"))) | AG34: =IF(O34="","",IF(X34="",O34,IF(O34=X34,O34,"DISCUSS"))) | AH34: =IF(P34="","",IF(Y34="",P34,IF(P34=Y34,P34,"DISCUSS"))) | AI34: =IF(Q34="","",IF(Z34="",Q34,IF(Q34=Z34,Q34,"DISCUSS"))) | AJ34: =IF(R34="","",IF(AA34="",R34,IF(R34=AA34,R34,"DISCUSS"))) | AK34: =IFERROR(AVERAGE(AB34:AJ34),"") | AL34: =COUNT(AB34:AJ34) -> 0 | AM34: =COUNTIF(AB34:AJ34,"DISCUSS") -> 0 | AN34: =IF(AL34=0,"",IF(AM34>0,"Resolve DISCUSS",IF(AL34<Tiers!$B$6,"Unrated",IF(AK34>=Tiers!$B$4,"High",IF(AK34>=Tiers!$B$5,"Medium","Low"))))) | AO34: =IF(OR(AN34="",AN34="Unrated",AN34="Resolve DISCUSS"),"",COUNTIFS($AN$6:$AN$105,AN34,$AK$6:$AK$105,">"&AK34)+1)
AB35: =IF(J35="","",IF(S35="",J35,IF(J35=S35,J35,"DISCUSS"))) | AC35: =IF(K35="","",IF(T35="",K35,IF(K35=T35,K35,"DISCUSS"))) | AD35: =IF(L35="","",IF(U35="",L35,IF(L35=U35,L35,"DISCUSS"))) | AE35: =IF(M35="","",IF(V35="",M35,IF(M35=V35,M35,"DISCUSS"))) | AF35: =IF(N35="","",IF(W35="",N35,IF(N35=W35,N35,"DISCUSS"))) | AG35: =IF(O35="","",IF(X35="",O35,IF(O35=X35,O35,"DISCUSS"))) | AH35: =IF(P35="","",IF(Y35="",P35,IF(P35=Y35,P35,"DISCUSS"))) | AI35: =IF(Q35="","",IF(Z35="",Q35,IF(Q35=Z35,Q35,"DISCUSS"))) | AJ35: =IF(R35="","",IF(AA35="",R35,IF(R35=AA35,R35,"DISCUSS"))) | AK35: =IFERROR(AVERAGE(AB35:AJ35),"") | AL35: =COUNT(AB35:AJ35) -> 0 | AM35: =COUNTIF(AB35:AJ35,"DISCUSS") -> 0 | AN35: =IF(AL35=0,"",IF(AM35>0,"Resolve DISCUSS",IF(AL35<Tiers!$B$6,"Unrated",IF(AK35>=Tiers!$B$4,"High",IF(AK35>=Tiers!$B$5,"Medium","Low"))))) | AO35: =IF(OR(AN35="",AN35="Unrated",AN35="Resolve DISCUSS"),"",COUNTIFS($AN$6:$AN$105,AN35,$AK$6:$AK$105,">"&AK35)+1)
AB36: =IF(J36="","",IF(S36="",J36,IF(J36=S36,J36,"DISCUSS"))) | AC36: =IF(K36="","",IF(T36="",K36,IF(K36=T36,K36,"DISCUSS"))) | AD36: =IF(L36="","",IF(U36="",L36,IF(L36=U36,L36,"DISCUSS"))) | AE36: =IF(M36="","",IF(V36="",M36,IF(M36=V36,M36,"DISCUSS"))) | AF36: =IF(N36="","",IF(W36="",N36,IF(N36=W36,N36,"DISCUSS"))) | AG36: =IF(O36="","",IF(X36="",O36,IF(O36=X36,O36,"DISCUSS"))) | AH36: =IF(P36="","",IF(Y36="",P36,IF(P36=Y36,P36,"DISCUSS"))) | AI36: =IF(Q36="","",IF(Z36="",Q36,IF(Q36=Z36,Q36,"DISCUSS"))) | AJ36: =IF(R36="","",IF(AA36="",R36,IF(R36=AA36,R36,"DISCUSS"))) | AK36: =IFERROR(AVERAGE(AB36:AJ36),"") | AL36: =COUNT(AB36:AJ36) -> 0 | AM36: =COUNTIF(AB36:AJ36,"DISCUSS") -> 0 | AN36: =IF(AL36=0,"",IF(AM36>0,"Resolve DISCUSS",IF(AL36<Tiers!$B$6,"Unrated",IF(AK36>=Tiers!$B$4,"High",IF(AK36>=Tiers!$B$5,"Medium","Low"))))) | AO36: =IF(OR(AN36="",AN36="Unrated",AN36="Resolve DISCUSS"),"",COUNTIFS($AN$6:$AN$105,AN36,$AK$6:$AK$105,">"&AK36)+1)
AB37: =IF(J37="","",IF(S37="",J37,IF(J37=S37,J37,"DISCUSS"))) | AC37: =IF(K37="","",IF(T37="",K37,IF(K37=T37,K37,"DISCUSS"))) | AD37: =IF(L37="","",IF(U37="",L37,IF(L37=U37,L37,"DISCUSS"))) | AE37: =IF(M37="","",IF(V37="",M37,IF(M37=V37,M37,"DISCUSS"))) | AF37: =IF(N37="","",IF(W37="",N37,IF(N37=W37,N37,"DISCUSS"))) | AG37: =IF(O37="","",IF(X37="",O37,IF(O37=X37,O37,"DISCUSS"))) | AH37: =IF(P37="","",IF(Y37="",P37,IF(P37=Y37,P37,"DISCUSS"))) | AI37: =IF(Q37="","",IF(Z37="",Q37,IF(Q37=Z37,Q37,"DISCUSS"))) | AJ37: =IF(R37="","",IF(AA37="",R37,IF(R37=AA37,R37,"DISCUSS"))) | AK37: =IFERROR(AVERAGE(AB37:AJ37),"") | AL37: =COUNT(AB37:AJ37) -> 0 | AM37: =COUNTIF(AB37:AJ37,"DISCUSS") -> 0 | AN37: =IF(AL37=0,"",IF(AM37>0,"Resolve DISCUSS",IF(AL37<Tiers!$B$6,"Unrated",IF(AK37>=Tiers!$B$4,"High",IF(AK37>=Tiers!$B$5,"Medium","Low"))))) | AO37: =IF(OR(AN37="",AN37="Unrated",AN37="Resolve DISCUSS"),"",COUNTIFS($AN$6:$AN$105,AN37,$AK$6:$AK$105,">"&AK37)+1)
AB38: =IF(J38="","",IF(S38="",J38,IF(J38=S38,J38,"DISCUSS"))) | AC38: =IF(K38="","",IF(T38="",K38,IF(K38=T38,K38,"DISCUSS"))) | AD38: =IF(L38="","",IF(U38="",L38,IF(L38=U38,L38,"DISCUSS"))) | AE38: =IF(M38="","",IF(V38="",M38,IF(M38=V38,M38,"DISCUSS"))) | AF38: =IF(N38="","",IF(W38="",N38,IF(N38=W38,N38,"DISCUSS"))) | AG38: =IF(O38="","",IF(X38="",O38,IF(O38=X38,O38,"DISCUSS"))) | AH38: =IF(P38="","",IF(Y38="",P38,IF(P38=Y38,P38,"DISCUSS"))) | AI38: =IF(Q38="","",IF(Z38="",Q38,IF(Q38=Z38,Q38,"DISCUSS"))) | AJ38: =IF(R38="","",IF(AA38="",R38,IF(R38=AA38,R38,"DISCUSS"))) | AK38: =IFERROR(AVERAGE(AB38:AJ38),"") | AL38: =COUNT(AB38:AJ38) -> 0 | AM38: =COUNTIF(AB38:AJ38,"DISCUSS") -> 0 | AN38: =IF(AL38=0,"",IF(AM38>0,"Resolve DISCUSS",IF(AL38<Tiers!$B$6,"Unrated",IF(AK38>=Tiers!$B$4,"High",IF(AK38>=Tiers!$B$5,"Medium","Low"))))) | AO38: =IF(OR(AN38="",AN38="Unrated",AN38="Resolve DISCUSS"),"",COUNTIFS($AN$6:$AN$105,AN38,$AK$6:$AK$105,">"&AK38)+1)
AB39: =IF(J39="","",IF(S39="",J39,IF(J39=S39,J39,"DISCUSS"))) | AC39: =IF(K39="","",IF(T39="",K39,IF(K39=T39,K39,"DISCUSS"))) | AD39: =IF(L39="","",IF(U39="",L39,IF(L39=U39,L39,"DISCUSS"))) | AE39: =IF(M39="","",IF(V39="",M39,IF(M39=V39,M39,"DISCUSS"))) | AF39: =IF(N39="","",IF(W39="",N39,IF(N39=W39,N39,"DISCUSS"))) | AG39: =IF(O39="","",IF(X39="",O39,IF(O39=X39,O39,"DISCUSS"))) | AH39: =IF(P39="","",IF(Y39="",P39,IF(P39=Y39,P39,"DISCUSS"))) | AI39: =IF(Q39="","",IF(Z39="",Q39,IF(Q39=Z39,Q39,"DISCUSS"))) | AJ39: =IF(R39="","",IF(AA39="",R39,IF(R39=AA39,R39,"DISCUSS"))) | AK39: =IFERROR(AVERAGE(AB39:AJ39),"") | AL39: =COUNT(AB39:AJ39) -> 0 | AM39: =COUNTIF(AB39:AJ39,"DISCUSS") -> 0 | AN39: =IF(AL39=0,"",IF(AM39>0,"Resolve DISCUSS",IF(AL39<Tiers!$B$6,"Unrated",IF(AK39>=Tiers!$B$4,"High",IF(AK39>=Tiers!$B$5,"Medium","Low"))))) | AO39: =IF(OR(AN39="",AN39="Unrated",AN39="Resolve DISCUSS"),"",COUNTIFS($AN$6:$AN$105,AN39,$AK$6:$AK$105,">"&AK39)+1)
AB40: =IF(J40="","",IF(S40="",J40,IF(J40=S40,J40,"DISCUSS"))) | AC40: =IF(K40="","",IF(T40="",K40,IF(K40=T40,K40,"DISCUSS"))) | AD40: =IF(L40="","",IF(U40="",L40,IF(L40=U40,L40,"DISCUSS"))) | AE40: =IF(M40="","",IF(V40="",M40,IF(M40=V40,M40,"DISCUSS"))) | AF40: =IF(N40="","",IF(W40="",N40,IF(N40=W40,N40,"DISCUSS"))) | AG40: =IF(O40="","",IF(X40="",O40,IF(O40=X40,O40,"DISCUSS"))) | AH40: =IF(P40="","",IF(Y40="",P40,IF(P40=Y40,P40,"DISCUSS"))) | AI40: =IF(Q40="","",IF(Z40="",Q40,IF(Q40=Z40,Q40,"DISCUSS"))) | AJ40: =IF(R40="","",IF(AA40="",R40,IF(R40=AA40,R40,"DISCUSS"))) | AK40: =IFERROR(AVERAGE(AB40:AJ40),"") | AL40: =COUNT(AB40:AJ40) -> 0 | AM40: =COUNTIF(AB40:AJ40,"DISCUSS") -> 0 | AN40: =IF(AL40=0,"",IF(AM40>0,"Resolve DISCUSS",IF(AL40<Tiers!$B$6,"Unrated",IF(AK40>=Tiers!$B$4,"High",IF(AK40>=Tiers!$B$5,"Medium","Low"))))) | AO40: =IF(OR(AN40="",AN40="Unrated",AN40="Resolve DISCUSS"),"",COUNTIFS($AN$6:$AN$105,AN40,$AK$6:$AK$105,">"&AK40)+1)
AB41: =IF(J41="","",IF(S41="",J41,IF(J41=S41,J41,"DISCUSS"))) | AC41: =IF(K41="","",IF(T41="",K41,IF(K41=T41,K41,"DISCUSS"))) | AD41: =IF(L41="","",IF(U41="",L41,IF(L41=U41,L41,"DISCUSS"))) | AE41: =IF(M41="","",IF(V41="",M41,IF(M41=V41,M41,"DISCUSS"))) | AF41: =IF(N41="","",IF(W41="",N41,IF(N41=W41,N41,"DISCUSS"))) | AG41: =IF(O41="","",IF(X41="",O41,IF(O41=X41,O41,"DISCUSS"))) | AH41: =IF(P41="","",IF(Y41="",P41,IF(P41=Y41,P41,"DISCUSS"))) | AI41: =IF(Q41="","",IF(Z41="",Q41,IF(Q41=Z41,Q41,"DISCUSS"))) | AJ41: =IF(R41="","",IF(AA41="",R41,IF(R41=AA41,R41,"DISCUSS"))) | AK41: =IFERROR(AVERAGE(AB41:AJ41),"") | AL41: =COUNT(AB41:AJ41) -> 0 | AM41: =COUNTIF(AB41:AJ41,"DISCUSS") -> 0 | AN41: =IF(AL41=0,"",IF(AM41>0,"Resolve DISCUSS",IF(AL41<Tiers!$B$6,"Unrated",IF(AK41>=Tiers!$B$4,"High",IF(AK41>=Tiers!$B$5,"Medium","Low"))))) | AO41: =IF(OR(AN41="",AN41="Unrated",AN41="Resolve DISCUSS"),"",COUNTIFS($AN$6:$AN$105,AN41,$AK$6:$AK$105,">"&AK41)+1)
AB42: =IF(J42="","",IF(S42="",J42,IF(J42=S42,J42,"DISCUSS"))) | AC42: =IF(K42="","",IF(T42="",K42,IF(K42=T42,K42,"DISCUSS"))) | AD42: =IF(L42="","",IF(U42="",L42,IF(L42=U42,L42,"DISCUSS"))) | AE42: =IF(M42="","",IF(V42="",M42,IF(M42=V42,M42,"DISCUSS"))) | AF42: =IF(N42="","",IF(W42="",N42,IF(N42=W42,N42,"DISCUSS"))) | AG42: =IF(O42="","",IF(X42="",O42,IF(O42=X42,O42,"DISCUSS"))) | AH42: =IF(P42="","",IF(Y42="",P42,IF(P42=Y42,P42,"DISCUSS"))) | AI42: =IF(Q42="","",IF(Z42="",Q42,IF(Q42=Z42,Q42,"DISCUSS"))) | AJ42: =IF(R42="","",IF(AA42="",R42,IF(R42=AA42,R42,"DISCUSS"))) | AK42: =IFERROR(AVERAGE(AB42:AJ42),"") | AL42: =COUNT(AB42:AJ42) -> 0 | AM42: =COUNTIF(AB42:AJ42,"DISCUSS") -> 0 | AN42: =IF(AL42=0,"",IF(AM42>0,"Resolve DISCUSS",IF(AL42<Tiers!$B$6,"Unrated",IF(AK42>=Tiers!$B$4,"High",IF(AK42>=Tiers!$B$5,"Medium","Low"))))) | AO42: =IF(OR(AN42="",AN42="Unrated",AN42="Resolve DISCUSS"),"",COUNTIFS($AN$6:$AN$105,AN42,$AK$6:$AK$105,">"&AK42)+1)
AB43: =IF(J43="","",IF(S43="",J43,IF(J43=S43,J43,"DISCUSS"))) | AC43: =IF(K43="","",IF(T43="",K43,IF(K43=T43,K43,"DISCUSS"))) | AD43: =IF(L43="","",IF(U43="",L43,IF(L43=U43,L43,"DISCUSS"))) | AE43: =IF(M43="","",IF(V43="",M43,IF(M43=V43,M43,"DISCUSS"))) | AF43: =IF(N43="","",IF(W43="",N43,IF(N43=W43,N43,"DISCUSS"))) | AG43: =IF(O43="","",IF(X43="",O43,IF(O43=X43,O43,"DISCUSS"))) | AH43: =IF(P43="","",IF(Y43="",P43,IF(P43=Y43,P43,"DISCUSS"))) | AI43: =IF(Q43="","",IF(Z43="",Q43,IF(Q43=Z43,Q43,"DISCUSS"))) | AJ43: =IF(R43="","",IF(AA43="",R43,IF(R43=AA43,R43,"DISCUSS"))) | AK43: =IFERROR(AVERAGE(AB43:AJ43),"") | AL43: =COUNT(AB43:AJ43) -> 0 | AM43: =COUNTIF(AB43:AJ43,"DISCUSS") -> 0 | AN43: =IF(AL43=0,"",IF(AM43>0,"Resolve DISCUSS",IF(AL43<Tiers!$B$6,"Unrated",IF(AK43>=Tiers!$B$4,"High",IF(AK43>=Tiers!$B$5,"Medium","Low"))))) | AO43: =IF(OR(AN43="",AN43="Unrated",AN43="Resolve DISCUSS"),"",COUNTIFS($AN$6:$AN$105,AN43,$AK$6:$AK$105,">"&AK43)+1)
AB44: =IF(J44="","",IF(S44="",J44,IF(J44=S44,J44,"DISCUSS"))) | AC44: =IF(K44="","",IF(T44="",K44,IF(K44=T44,K44,"DISCUSS"))) | AD44: =IF(L44="","",IF(U44="",L44,IF(L44=U44,L44,"DISCUSS"))) | AE44: =IF(M44="","",IF(V44="",M44,IF(M44=V44,M44,"DISCUSS"))) | AF44: =IF(N44="","",IF(W44="",N44,IF(N44=W44,N44,"DISCUSS"))) | AG44: =IF(O44="","",IF(X44="",O44,IF(O44=X44,O44,"DISCUSS"))) | AH44: =IF(P44="","",IF(Y44="",P44,IF(P44=Y44,P44,"DISCUSS"))) | AI44: =IF(Q44="","",IF(Z44="",Q44,IF(Q44=Z44,Q44,"DISCUSS"))) | AJ44: =IF(R44="","",IF(AA44="",R44,IF(R44=AA44,R44,"DISCUSS"))) | AK44: =IFERROR(AVERAGE(AB44:AJ44),"") | AL44: =COUNT(AB44:AJ44) -> 0 | AM44: =COUNTIF(AB44:AJ44,"DISCUSS") -> 0 | AN44: =IF(AL44=0,"",IF(AM44>0,"Resolve DISCUSS",IF(AL44<Tiers!$B$6,"Unrated",IF(AK44>=Tiers!$B$4,"High",IF(AK44>=Tiers!$B$5,"Medium","Low"))))) | AO44: =IF(OR(AN44="",AN44="Unrated",AN44="Resolve DISCUSS"),"",COUNTIFS($AN$6:$AN$105,AN44,$AK$6:$AK$105,">"&AK44)+1)
AB45: =IF(J45="","",IF(S45="",J45,IF(J45=S45,J45,"DISCUSS"))) | AC45: =IF(K45="","",IF(T45="",K45,IF(K45=T45,K45,"DISCUSS"))) | AD45: =IF(L45="","",IF(U45="",L45,IF(L45=U45,L45,"DISCUSS"))) | AE45: =IF(M45="","",IF(V45="",M45,IF(M45=V45,M45,"DISCUSS"))) | AF45: =IF(N45="","",IF(W45="",N45,IF(N45=W45,N45,"DISCUSS"))) | AG45: =IF(O45="","",IF(X45="",O45,IF(O45=X45,O45,"DISCUSS"))) | AH45: =IF(P45="","",IF(Y45="",P45,IF(P45=Y45,P45,"DISCUSS"))) | AI45: =IF(Q45="","",IF(Z45="",Q45,IF(Q45=Z45,Q45,"DISCUSS"))) | AJ45: =IF(R45="","",IF(AA45="",R45,IF(R45=AA45,R45,"DISCUSS"))) | AK45: =IFERROR(AVERAGE(AB45:AJ45),"") | AL45: =COUNT(AB45:AJ45) -> 0 | AM45: =COUNTIF(AB45:AJ45,"DISCUSS") -> 0 | AN45: =IF(AL45=0,"",IF(AM45>0,"Resolve DISCUSS",IF(AL45<Tiers!$B$6,"Unrated",IF(AK45>=Tiers!$B$4,"High",IF(AK45>=Tiers!$B$5,"Medium","Low"))))) | AO45: =IF(OR(AN45="",AN45="Unrated",AN45="Resolve DISCUSS"),"",COUNTIFS($AN$6:$AN$105,AN45,$AK$6:$AK$105,">"&AK45)+1)
